Workbook

Sheet CLIENTES ACTIVOS
A1: Ejecutivo | B1: Nombre Cliente | C1: Merchant ID | D1: Creado en CRM | E1: Mes Año | F1: Fecha de activacion | G1: Mes | H1: Año | I1: ORIGEN del Cliente | J1: Si es referido Correo electronico De quien refiere de no ser asi dejar N/A | K1: TPV Potencial en MIllones | L1: Tarifa Aplicada | M1: DATAFONOS | N1: QR-LINK-BOTON | O1: CONTRATOS FRAUDE | P1: CONTRATOS | Q1: TPV M0 | R1: TPV M1 | S1: TPV M2 | T1: TPV M3 | U1: PROMEDIO TPV | V1: Se entrega a CS | W1: KAM que recibe Comercio
A2: jhonatan.torres@bold.co | B2: Ferrelectric El Proveedor | C2: OTT8ZA91GS | D2: Si | E2: =TEXT(F2, "mmmm yyyy") -> enero 2024 | F2: 45296 | G2: =F2 -> 45296 | H2: =G2 -> 45296 | I2: SI | J2: luis.castellar@bold.co | K2: 50000000 | L2: 2,19 +300 | Q2: =VLOOKUP(C2,QS!E:AB,21,0) -> #REF! | R2: =VLOOKUP(C2,QS!E:AB,22,0) -> #REF! | S2: =VLOOKUP(C2,QS!E:AB,23,0) -> #REF! | T2: =VLOOKUP(C2,QS!E:AB,24,0) -> #REF!
A3: juan.salgado@bold.co | B3: JANGUEO CARTAGENA | C3: LWU5FIZZPX | D3: Si | E3: =TEXT(F3, "mmmm yyyy") -> enero 2024 | F3: 45303 | G3: =F3 -> 45303 | H3: =G3 -> 45303 | I3: SI | J3: Estefanía.torres@bold.co | K3: 50000000 | L3: 2,19+$300 | P3: Pendientes | Q3: =VLOOKUP(C3,QS!E:AB,21,0) -> #REF! | R3: =VLOOKUP(C3,QS!E:AB,22,0) -> #REF! | S3: =VLOOKUP(C3,QS!E:AB,23,0) -> #REF! | T3: =VLOOKUP(C3,QS!E:AB,24,0) -> #REF!
A4: jhonatan.moreno@bold.co | B4: Majestic burgers | C4: 7IW47CWHLA | D4: Si | E4: =TEXT(F4, "mmmm yyyy") -> enero 2024 | F4: 45306 | G4: =F4 -> 45306 | H4: =G4 -> 45306 | I4: Referido Outbound | J4: jaime.barrios@bold.co | K4: 150000000 | L4: 2,19+$300 | P4: Si | Q4: =VLOOKUP(C4,QS!E:AB,21,0) -> #REF! | R4: =VLOOKUP(C4,QS!E:AB,22,0) -> #REF! | S4: =VLOOKUP(C4,QS!E:AB,23,0) -> #REF! | T4: =VLOOKUP(C4,QS!E:AB,24,0) -> #REF!
A5: jhonatan.moreno@bold.co | B5: caribean team | C5: PM6BZ0OM41 | D5: Si | E5: =TEXT(F5, "mmmm yyyy") -> enero 2024 | F5: 45308 | G5: =F5 -> 45308 | H5: =G5 -> 45308 | I5: Referido Outbound | J5: jaime.barrios@bold.co | L5: 2,19+$300 | P5: Si | Q5: =VLOOKUP(C5,QS!E:AB,21,0) -> #REF! | R5: =VLOOKUP(C5,QS!E:AB,22,0) -> #REF! | S5: =VLOOKUP(C5,QS!E:AB,23,0) -> #REF! | T5: =VLOOKUP(C5,QS!E:AB,24,0) -> #REF!
A6: jhonatan.moreno@bold.co | B6: Tolifruver | C6: V2D10H30A6 | D6: Si | E6: =TEXT(F6, "mmmm yyyy") -> enero 2024 | F6: 45308 | G6: =F6 -> 45308 | H6: =G6 -> 45308 | I6: Cliente Propio | K6: 40000000 | L6: 2,39 + 300 | Q6: =VLOOKUP(C6,QS!E:AB,21,0) -> #REF! | R6: =VLOOKUP(C6,QS!E:AB,22,0) -> #REF! | S6: =VLOOKUP(C6,QS!E:AB,23,0) -> #REF! | T6: =VLOOKUP(C6,QS!E:AB,24,0) -> #REF!
A7: angel.lesmes@bold.co | B7: Manns Design | C7: W9Y4L8F4N2 | D7: Si | E7: =TEXT(F7, "mmmm yyyy") -> enero 2024 | F7: 45309 | G7: =F7 -> 45309 | H7: =G7 -> 45309 | K7: 30000000 | L7: 2,89+300 | Q7: =VLOOKUP(C7,QS!E:AB,21,0) -> #REF! | R7: =VLOOKUP(C7,QS!E:AB,22,0) -> #REF! | S7: =VLOOKUP(C7,QS!E:AB,23,0) -> #REF! | T7: =VLOOKUP(C7,QS!E:AB,24,0) -> #REF!
A8: jhonatan.moreno@bold.co | B8: Macro pollos | C8: AYILZWWK0P | D8: Si | E8: =TEXT(F8, "mmmm yyyy") -> enero 2024 | F8: 45316 | G8: =F8 -> 45316 | H8: =G8 -> 45316 | I8: Referido Outbound | J8: andres.cardozo@bold.co | K8: 20000000 | L8: 2,29+300 | P8: Si | Q8: =VLOOKUP(C8,QS!E:AB,21,0) -> #REF! | R8: =VLOOKUP(C8,QS!E:AB,22,0) -> #REF! | S8: =VLOOKUP(C8,QS!E:AB,23,0) -> #REF! | T8: =VLOOKUP(C8,QS!E:AB,24,0) -> #REF!
A9: luis.corredor@bold.co | B9: Sofiian Cedritos | C9: ARYDJSNS2X | D9: Si | E9: =TEXT(F9, "mmmm yyyy") -> enero 2024 | F9: 45316 | G9: =F9 -> 45316 | H9: =G9 -> 45316 | I9: Cliente Propio | K9: 35000000 | L9: 2,19 +300 | Q9: =VLOOKUP(C9,QS!E:AB,21,0) -> #REF! | R9: =VLOOKUP(C9,QS!E:AB,22,0) -> #REF! | S9: =VLOOKUP(C9,QS!E:AB,23,0) -> #REF! | T9: =VLOOKUP(C9,QS!E:AB,24,0) -> #REF!
A10: luis.corredor@bold.co | B10: Veolia | C10: D9BBCAUZRK | D10: Si | E10: =TEXT(F10, "mmmm yyyy") -> enero 2024 | F10: 45316 | G10: =F10 -> 45316 | H10: =G10 -> 45316 | I10: Cliente Propio | J10: lorena.oviedo@bold.co | K10: 150000000 | L10: 2.19 | P10: Pendientes | Q10: =VLOOKUP(C10,QS!E:AB,21,0) -> #REF! | R10: =VLOOKUP(C10,QS!E:AB,22,0) -> #REF! | S10: =VLOOKUP(C10,QS!E:AB,23,0) -> #REF! | T10: =VLOOKUP(C10,QS!E:AB,24,0) -> #REF!
A11: jhonatan.torres@bold.co | B11: DECORADOS Y ACABADOS CERMAMICOS | C11: MLSOQIAORD | D11: Si | E11: =TEXT(F11, "mmmm yyyy") -> enero 2024 | F11: 45316 | G11: =F11 -> 45316 | H11: =G11 -> 45316 | I11: No | K11: 200000000 | L11: 1.99 | P11: Pendientes | Q11: =VLOOKUP(C11,QS!E:AB,21,0) -> #REF! | R11: =VLOOKUP(C11,QS!E:AB,22,0) -> #REF! | S11: =VLOOKUP(C11,QS!E:AB,23,0) -> #REF! | T11: =VLOOKUP(C11,QS!E:AB,24,0) -> #REF!
A12: jhonatan.moreno@bold.co | B12: BEYROUTH 93 | C12: ZBFT9JBRNT | D12: Si | E12: =TEXT(F12, "mmmm yyyy") -> enero 2024 | F12: 45317 | G12: =F12 -> 45317 | H12: =G12 -> 45317 | I12: Referido Outbound | J12: margareth.arias@bold.co | K12: 200000000 | L12: 2.05 | Q12: =VLOOKUP(C12,QS!E:AB,21,0) -> #REF! | R12: =VLOOKUP(C12,QS!E:AB,22,0) -> #REF! | S12: =VLOOKUP(C12,QS!E:AB,23,0) -> #REF! | T12: =VLOOKUP(C12,QS!E:AB,24,0) -> #REF!
A13: luis.corredor@bold.co | B13: CASSARENA | C13: W06BXLMD3C | D13: Si | E13: =TEXT(F13, "mmmm yyyy") -> enero 2024 | F13: 45318 | G13: =F13 -> 45318 | H13: =G13 -> 45318 | I13: SI | J13: andres.cardozo@bold.co | K13: 100000000 | L13: 2,19+300 | P13: Si | Q13: =VLOOKUP(C13,QS!E:AB,21,0) -> #REF! | R13: =VLOOKUP(C13,QS!E:AB,22,0) -> #REF! | S13: =VLOOKUP(C13,QS!E:AB,23,0) -> #REF! | T13: =VLOOKUP(C13,QS!E:AB,24,0) -> #REF!
A14: jhonatan.moreno@bold.co | B14: ALFAPARF | C14: VOG2HUW5VO | D14: Si | E14: =TEXT(F14, "mmmm yyyy") -> febrero 2024 | F14: 45323 | G14: =F14 -> 45323 | H14: =G14 -> 45323 | I14: Cliente Propio | K14: 250000000 | L14: 2,19+$300 | Q14: =VLOOKUP(C14,QS!E:AB,21,0) -> #REF! | R14: =VLOOKUP(C14,QS!E:AB,22,0) -> #REF! | S14: =VLOOKUP(C14,QS!E:AB,23,0) -> #REF! | T14: =VLOOKUP(C14,QS!E:AB,24,0) -> #REF!
A15: jhonatan.moreno@bold.co | B15: Surubi Food | C15: VIFU5YJBTM | D15: Si | E15: =TEXT(F15, "mmmm yyyy") -> febrero 2024 | F15: 45324 | G15: =F15 -> 45324 | H15: =G15 -> 45324 | I15: Referido Outbound | J15: jaime.barrios@bold.co | K15: 100000000 | L15: 2,19+$300 | P15: Si | Q15: =VLOOKUP(C15,QS!E:AB,21,0) -> #REF! | R15: =VLOOKUP(C15,QS!E:AB,22,0) -> #REF! | S15: =VLOOKUP(C15,QS!E:AB,23,0) -> #REF! | T15: =VLOOKUP(C15,QS!E:AB,24,0) -> #REF!
A16: luis.corredor@bold.co | B16: Miguel Burger | C16: DQDQKMENXA | D16: Si | E16: =TEXT(F16, "mmmm yyyy") -> febrero 2024 | F16: 45324 | G16: =F16 -> 45324 | H16: =G16 -> 45324 | I16: No | K16: 160000000 | L16: 2,09+$100 | P16: Si | Q16: =VLOOKUP(C16,QS!E:AB,21,0) -> #REF! | R16: =VLOOKUP(C16,QS!E:AB,22,0) -> #REF! | S16: =VLOOKUP(C16,QS!E:AB,23,0) -> #REF! | T16: =VLOOKUP(C16,QS!E:AB,24,0) -> #REF!
A17: angel.lesmes@bold.co | B17: Restaurante Musashi | C17: QKCESKPA91 | D17: Si | E17: =TEXT(F17, "mmmm yyyy") -> febrero 2024 | F17: 45336 | G17: =F17 -> 45336 | H17: =G17 -> 45336 | I17: No | K17: 20000000 | L17: 2,19% + $300 | P17: Pendientes | Q17: =VLOOKUP(C17,QS!E:AB,21,0) -> #REF! | R17: =VLOOKUP(C17,QS!E:AB,22,0) -> #REF! | S17: =VLOOKUP(C17,QS!E:AB,23,0) -> #REF! | T17: =VLOOKUP(C17,QS!E:AB,24,0) -> #REF!
A18: angel.lesmes@bold.co | B18: Restaurante Musashi | C18: YE6RMJFK6K | D18: Si | E18: =TEXT(F18, "mmmm yyyy") -> febrero 2024 | F18: 45336 | G18: =F18 -> 45336 | H18: =G18 -> 45336 | I18: No | K18: 20000000 | L18: 2,19% + $300 | P18: Pendientes | Q18: =VLOOKUP(C18,QS!E:AB,21,0) -> #REF! | R18: =VLOOKUP(C18,QS!E:AB,22,0) -> #REF! | S18: =VLOOKUP(C18,QS!E:AB,23,0) -> #REF! | T18: =VLOOKUP(C18,QS!E:AB,24,0) -> #REF!
A19: jhonatan.torres@bold.co | B19: Artesanal | C19: YEY17SS4UP | D19: Si | E19: =TEXT(F19, "mmmm yyyy") -> febrero 2024 | F19: 45336 | G19: =F19 -> 45336 | H19: =G19 -> 45336 | I19: Referido Outbound | J19: luis.correa@bold.co | K19: 100000000 | L19: 2,19% + $300 | Q19: =VLOOKUP(C19,QS!E:AB,21,0) -> #REF! | R19: =VLOOKUP(C19,QS!E:AB,22,0) -> #REF! | S19: =VLOOKUP(C19,QS!E:AB,23,0) -> #REF! | T19: =VLOOKUP(C19,QS!E:AB,24,0) -> #REF!
A20: angel.lesmes@bold.co | B20: Almacén Y Taller Todo Nissan Ayt Sas | C20: VTCXH9AYXO | D20: Si | E20: =TEXT(F20, "mmmm yyyy") -> febrero 2024 | F20: 45337 | G20: =F20 -> 45337 | H20: =G20 -> 45337 | I20: Cliente Propio | K20: 50000000 | L20: 2,19% + $300 | P20: Pendientes | Q20: =VLOOKUP(C20,QS!E:AB,21,0) -> #REF! | R20: =VLOOKUP(C20,QS!E:AB,22,0) -> #REF! | S20: =VLOOKUP(C20,QS!E:AB,23,0) -> #REF! | T20: =VLOOKUP(C20,QS!E:AB,24,0) -> #REF!
A21: cristian.baquero@bold.co | B21: Acabados dyp | C21: CGTPT8L3DG | D21: Si | E21: =TEXT(F21, "mmmm yyyy") -> febrero 2024 | F21: 45332 | G21: =F21 -> 45332 | H21: =G21 -> 45332 | I21: Cliente Propio | K21: 30000000 | L21: 2,19% + $300 | Q21: =VLOOKUP(C21,QS!E:AB,21,0) -> #REF! | R21: =VLOOKUP(C21,QS!E:AB,22,0) -> #REF! | S21: =VLOOKUP(C21,QS!E:AB,23,0) -> #REF! | T21: =VLOOKUP(C21,QS!E:AB,24,0) -> #REF!
A22: cristian.baquero@bold.co | B22: Dukari | C22: CBL16SJULR | D22: Si | E22: =TEXT(F22, "mmmm yyyy") -> febrero 2024 | F22: 45334 | G22: =F22 -> 45334 | H22: =G22 -> 45334 | I22: Cliente Propio | K22: 50000000 | L22: 2,59% + $900 (solo Link) | Q22: 482000 | R22: =VLOOKUP(C22,QS!E:AB,22,0) -> #REF! | S22: =VLOOKUP(C22,QS!E:AB,23,0) -> #REF! | T22: =VLOOKUP(C22,QS!E:AB,24,0) -> #REF!
A23: cristian.baquero@bold.co | B23: Lebog | C23: EO5ZB49DG2 | D23: Si | E23: =TEXT(F23, "mmmm yyyy") -> febrero 2024 | F23: 45336 | G23: =F23 -> 45336 | H23: =G23 -> 45336 | I23: Cliente Propio | K23: 50000000 | L23: 2,19% + $300 | Q23: =VLOOKUP(C23,QS!E:AB,21,0) -> #REF! | R23: =VLOOKUP(C23,QS!E:AB,22,0) -> #REF! | S23: =VLOOKUP(C23,QS!E:AB,23,0) -> #REF! | T23: =VLOOKUP(C23,QS!E:AB,24,0) -> #REF!
A24: cristian.baquero@bold.co | B24: Foodology | C24: OFC2I4Z2PO | D24: Si | E24: =TEXT(F24, "mmmm yyyy") -> febrero 2024 | F24: 45342 | G24: =F24 -> 45342 | H24: =G24 -> 45342 | I24: Referido Outbound | J24: cristian.casas@bold.co | K24: 600000000 | L24: 0.0199 | P24: Pendientes | Q24: =VLOOKUP(C24,QS!E:AB,21,0) -> #REF! | R24: =VLOOKUP(C24,QS!E:AB,22,0) -> #REF! | S24: =VLOOKUP(C24,QS!E:AB,23,0) -> #REF! | T24: =VLOOKUP(C24,QS!E:AB,24,0) -> #REF!
A25: angel.lesmes@bold.co | B25: Medina Golden | C25: DUJE9XZH3Q | D25: Si | E25: =TEXT(F25, "mmmm yyyy") -> febrero 2024 | F25: 45345 | G25: =F25 -> 45345 | H25: =G25 -> 45345 | I25: Cliente Propio | K25: 100000000 | L25: 1.99 | P25: Pendientes | Q25: =VLOOKUP(C25,QS!E:AB,21,0) -> #REF! | R25: =VLOOKUP(C25,QS!E:AB,22,0) -> #REF! | S25: =VLOOKUP(C25,QS!E:AB,23,0) -> #REF! | T25: =VLOOKUP(C25,QS!E:AB,24,0) -> #REF!
A26: luis.corredor@bold.co | B26: Beef PuraRaza | C26: NY6646ULTO | D26: Si | E26: =TEXT(F26, "mmmm yyyy") -> febrero 2024 | F26: 45345 | G26: =F26 -> 45345 | H26: =G26 -> 45345 | I26: Referido Spiders | J26: angie.rodriguez@bold.co | K26: 150000000 | L26: 2,09+$100 | P26: Si | Q26: =VLOOKUP(C26,QS!E:AB,21,0) -> #REF! | R26: =VLOOKUP(C26,QS!E:AB,22,0) -> #REF! | S26: =VLOOKUP(C26,QS!E:AB,23,0) -> #REF! | T26: =VLOOKUP(C26,QS!E:AB,24,0) -> #REF!
A27: jhonatan.moreno@bold.co | B27: LA FINCA DE RIGOLLANOGRANDE | C27: 1AG1WY7CSP | D27: Si | E27: =TEXT(F27, "mmmm yyyy") -> marzo 2024 | F27: 45352 | G27: =F27 -> 45352 | H27: =G27 -> 45352 | I27: Referido Spiders | J27: angie.rodriguez@bold.co | K27: 200000000 | P27: Pendientes
A28: jhonatan.moreno@bold.co | B28: GO RIGO GO PALMAS | C28: 3F86R9UN91 | D28: Si | E28: =TEXT(F28, "mmmm yyyy") -> marzo 2024 | F28: 45352 | G28: =F28 -> 45352 | H28: =G28 -> 45352 | I28: Referido Spiders | J28: sandra.robayo@bold.co | K28: 200000000 | P28: Pendientes
A29: luis.corredor@bold.co | B29: Zona cafe y pan | C29: C2T5G954F1 | D29: Si | E29: =TEXT(F29, "mmmm yyyy") -> marzo 2024 | F29: 45352 | G29: =F29 -> 45352 | H29: =G29 -> 45352 | I29: Referido Spiders | J29: nazareth.ruiz@bold.co | K29: 40000000 | L29: 2,19% + $300
A30: angel.lesmes@bold.co | B30: Mi Tierra | C30: T0EM6PSD79 | D30: Si | E30: =TEXT(F30, "mmmm yyyy") -> marzo 2024 | F30: 45352 | G30: =F30 -> 45352 | H30: =G30 -> 45352 | I30: Referido Spiders | J30: milton.ortiz@bold.co | K30: 50000000 | L30: 2,19% + $300
A31: jhonatan.moreno@bold.co | B31: GRACIES | C31: PQFEX2AY4O | D31: Si | E31: =TEXT(F31, "mmmm yyyy") -> marzo 2024 | F31: 45355 | G31: =F31 -> 45355 | H31: =G31 -> 45355 | I31: Cliente Propio | K31: 80000000 | L31: 2.19
A32: jhonatan.moreno@bold.co | B32: COLTOLIMA | C32: KUQFCYOJ5F | D32: Si | E32: =TEXT(F32, "mmmm yyyy") -> marzo 2024 | F32: 45355 | G32: =F32 -> 45355 | H32: =G32 -> 45355 | I32: Cliente Propio | P32: Pendientes
A33: luis.corredor@bold.co | B33: Veolia Archipiélago sas esp | C33: YO5Y2NTPRY | D33: Si | E33: =TEXT(F33, "mmmm yyyy") -> marzo 2024 | F33: 45355 | G33: =F33 -> 45355 | H33: =G33 -> 45355 | I33: Referido Outbound | J33: edwar.sinisterra@bold.co | K33: 150000000 | L33: 2.19 | P33: Revision
A34: cristian.baquero@bold.co | B34: Rosalba Sanchez | C34: 1MEOXAZD4L | D34: Si | E34: =TEXT(F34, "mmmm yyyy") -> marzo 2024 | F34: 45356 | G34: =F34 -> 45356 | H34: =G34 -> 45356 | I34: Referido Spiders | J34: angie.rodriguez@bold.co | K34: 80000000 | L34: 2,19 + $300 | P34: Pendientes
A35: cristian.baquero@bold.co | B35: VFS Colombia SAS | C35: W522Q392Y7 | D35: Si | E35: =TEXT(F35, "mmmm yyyy") -> marzo 2024 | F35: 45356 | G35: =F35 -> 45356 | H35: =G35 -> 45356 | I35: Referido Spiders | J35: milton.ortiz@bold.co | K35: 400000000 | L35: 0.0199 | P35: Pendientes
A36: cristian.baquero@bold.co | B36: VFS Colombia SAS | C36: PZKOSYJEEO | D36: Si | E36: =TEXT(F36, "mmmm yyyy") -> marzo 2024 | F36: 45356 | G36: =F36 -> 45356 | H36: =G36 -> 45356 | I36: Referido Spiders | J36: milton.ortiz@bold.co | K36: 400000000 | L36: 0.0199 | P36: Pendientes
A37: cristian.baquero@bold.co | B37: VFS Colombia SAS | C37: W636X85VHW | D37: Si | E37: =TEXT(F37, "mmmm yyyy") -> marzo 2024 | F37: 45356 | G37: =F37 -> 45356 | H37: =G37 -> 45356 | I37: Referido Spiders | J37: milton.ortiz@bold.co | K37: 400000000 | L37: 0.0199 | P37: Pendientes
A38: jhonatan.moreno@bold.co | B38: German Summa | C38: 0NAMJ65HII | D38: Si | E38: =TEXT(F38, "mmmm yyyy") -> marzo 2024 | F38: 45363 | G38: =F38 -> 45363 | H38: =G38 -> 45363 | I38: Cliente Propio | K38: 40000000
A39: luis.corredor@bold.co | B39: Combos cosmicos portal 80 | C39: OFZJDWZPTJ | D39: Si | E39: =TEXT(F39, "mmmm yyyy") -> marzo 2024 | F39: 45363 | G39: =F39 -> 45363 | H39: =G39 -> 45363 | I39: Cliente Propio | K39: 30000000 | L39: 2,19 + $300
A40: jhonatan.moreno@bold.co | B40: Atractiva Calzados | C40: TP4LNEUN1M | D40: Si | E40: =TEXT(F40, "mmmm yyyy") -> marzo 2024 | F40: 45365 | G40: =F40 -> 45365 | H40: =G40 -> 45365 | I40: Cliente Propio | K40: 30000000 | L40: 2,19 + $300
...

Sheet Copia de CLIENTES ACTIVOS
A1: Ejecutivo | B1: Nombre Cliente | C1: Merchant ID | D1: Creado en CRM | E1: Mes Año | F1: Fecha de activacion | G1: Mes | H1: Año | I1: ORIGEN del Cliente | J1: Si es referido Correo electronico De quien refiere de no ser asi dejar N/A | K1: TPV Potencial en MIllones | L1: Tarifa Aplicada | M1: DATAFONOS | N1: QR-LINK-BOTON | O1: CONTRATOS FRAUDE | P1: CONTRATOS | Q1: TPV M0 | R1: TPV M1 | S1: TPV M2 | T1: TPV M3 | U1: PROMEDIO TPV | V1: Se entrega a CS | W1: KAM que recibe Comercio
A2: jhonatan.torres@bold.co | B2: Ferrelectric El Proveedor | C2: OTT8ZA91GS | D2: Si | E2: =TEXT(F2, "mmmm yyyy") -> enero 2024 | F2: 45296 | G2: =F2 -> 45296 | H2: =G2 -> 45296 | I2: SI | J2: luis.castellar@bold.co | K2: 50000000 | L2: 2,19 +300 | Q2: =VLOOKUP(C2,QS!E:AB,21,0) -> #REF! | R2: =VLOOKUP(C2,QS!E:AB,22,0) -> #REF! | S2: =VLOOKUP(C2,QS!E:AB,23,0) -> #REF! | T2: =VLOOKUP(C2,QS!E:AB,24,0) -> #REF!
A3: juan.salgado@bold.co | B3: JANGUEO CARTAGENA | C3: LWU5FIZZPX | D3: Si | E3: =TEXT(F3, "mmmm yyyy") -> enero 2024 | F3: 45303 | G3: =F3 -> 45303 | H3: =G3 -> 45303 | I3: SI | J3: Estefanía.torres@bold.co | K3: 50000000 | L3: 2,19+$300 | P3: Pendientes | Q3: =VLOOKUP(C3,QS!E:AB,21,0) -> #REF! | R3: =VLOOKUP(C3,QS!E:AB,22,0) -> #REF! | S3: =VLOOKUP(C3,QS!E:AB,23,0) -> #REF! | T3: =VLOOKUP(C3,QS!E:AB,24,0) -> #REF!
A4: jhonatan.moreno@bold.co | B4: Majestic burgers | C4: 7IW47CWHLA | D4: Si | E4: =TEXT(F4, "mmmm yyyy") -> enero 2024 | F4: 45306 | G4: =F4 -> 45306 | H4: =G4 -> 45306 | I4: Referido Outbound | J4: jaime.barrios@bold.co | K4: 150000000 | L4: 2,19+$300 | P4: Si | Q4: =VLOOKUP(C4,QS!E:AB,21,0) -> #REF! | R4: =VLOOKUP(C4,QS!E:AB,22,0) -> #REF! | S4: =VLOOKUP(C4,QS!E:AB,23,0) -> #REF! | T4: =VLOOKUP(C4,QS!E:AB,24,0) -> #REF!
A5: jhonatan.moreno@bold.co | B5: caribean team | C5: PM6BZ0OM41 | D5: Si | E5: =TEXT(F5, "mmmm yyyy") -> enero 2024 | F5: 45308 | G5: =F5 -> 45308 | H5: =G5 -> 45308 | I5: Referido Outbound | J5: jaime.barrios@bold.co | L5: 2,19+$300 | P5: Si | Q5: =VLOOKUP(C5,QS!E:AB,21,0) -> #REF! | R5: =VLOOKUP(C5,QS!E:AB,22,0) -> #REF! | S5: =VLOOKUP(C5,QS!E:AB,23,0) -> #REF! | T5: =VLOOKUP(C5,QS!E:AB,24,0) -> #REF!
A6: jhonatan.moreno@bold.co | B6: Tolifruver | C6: V2D10H30A6 | D6: Si | E6: =TEXT(F6, "mmmm yyyy") -> enero 2024 | F6: 45308 | G6: =F6 -> 45308 | H6: =G6 -> 45308 | I6: Cliente Propio | K6: 40000000 | L6: 2,39 + 300 | Q6: =VLOOKUP(C6,QS!E:AB,21,0) -> #REF! | R6: =VLOOKUP(C6,QS!E:AB,22,0) -> #REF! | S6: =VLOOKUP(C6,QS!E:AB,23,0) -> #REF! | T6: =VLOOKUP(C6,QS!E:AB,24,0) -> #REF!
A7: angel.lesmes@bold.co | B7: Manns Design | C7: W9Y4L8F4N2 | D7: Si | E7: =TEXT(F7, "mmmm yyyy") -> enero 2024 | F7: 45309 | G7: =F7 -> 45309 | H7: =G7 -> 45309 | K7: 30000000 | L7: 2,89+300 | Q7: =VLOOKUP(C7,QS!E:AB,21,0) -> #REF! | R7: =VLOOKUP(C7,QS!E:AB,22,0) -> #REF! | S7: =VLOOKUP(C7,QS!E:AB,23,0) -> #REF! | T7: =VLOOKUP(C7,QS!E:AB,24,0) -> #REF!
A8: jhonatan.moreno@bold.co | B8: Macro pollos | C8: AYILZWWK0P | D8: Si | E8: =TEXT(F8, "mmmm yyyy") -> enero 2024 | F8: 45316 | G8: =F8 -> 45316 | H8: =G8 -> 45316 | I8: Referido Outbound | J8: andres.cardozo@bold.co | K8: 20000000 | L8: 2,29+300 | P8: Si | Q8: =VLOOKUP(C8,QS!E:AB,21,0) -> #REF! | R8: =VLOOKUP(C8,QS!E:AB,22,0) -> #REF! | S8: =VLOOKUP(C8,QS!E:AB,23,0) -> #REF! | T8: =VLOOKUP(C8,QS!E:AB,24,0) -> #REF!
A9: luis.corredor@bold.co | B9: Sofiian Cedritos | C9: ARYDJSNS2X | D9: Si | E9: =TEXT(F9, "mmmm yyyy") -> enero 2024 | F9: 45316 | G9: =F9 -> 45316 | H9: =G9 -> 45316 | I9: Cliente Propio | K9: 35000000 | L9: 2,19 +300 | Q9: =VLOOKUP(C9,QS!E:AB,21,0) -> #REF! | R9: =VLOOKUP(C9,QS!E:AB,22,0) -> #REF! | S9: =VLOOKUP(C9,QS!E:AB,23,0) -> #REF! | T9: =VLOOKUP(C9,QS!E:AB,24,0) -> #REF!
A10: luis.corredor@bold.co | B10: Veolia | C10: D9BBCAUZRK | D10: Si | E10: =TEXT(F10, "mmmm yyyy") -> enero 2024 | F10: 45316 | G10: =F10 -> 45316 | H10: =G10 -> 45316 | I10: Cliente Propio | J10: lorena.oviedo@bold.co | K10: 150000000 | L10: 2.19 | P10: Pendientes | Q10: =VLOOKUP(C10,QS!E:AB,21,0) -> #REF! | R10: =VLOOKUP(C10,QS!E:AB,22,0) -> #REF! | S10: =VLOOKUP(C10,QS!E:AB,23,0) -> #REF! | T10: =VLOOKUP(C10,QS!E:AB,24,0) -> #REF!
A11: jhonatan.torres@bold.co | B11: DECORADOS Y ACABADOS CERMAMICOS | C11: MLSOQIAORD | D11: Si | E11: =TEXT(F11, "mmmm yyyy") -> enero 2024 | F11: 45316 | G11: =F11 -> 45316 | H11: =G11 -> 45316 | I11: No | K11: 200000000 | L11: 1.99 | P11: Pendientes | Q11: =VLOOKUP(C11,QS!E:AB,21,0) -> #REF! | R11: =VLOOKUP(C11,QS!E:AB,22,0) -> #REF! | S11: =VLOOKUP(C11,QS!E:AB,23,0) -> #REF! | T11: =VLOOKUP(C11,QS!E:AB,24,0) -> #REF!
A12: jhonatan.moreno@bold.co | B12: BEYROUTH 93 | C12: ZBFT9JBRNT | D12: Si | E12: =TEXT(F12, "mmmm yyyy") -> enero 2024 | F12: 45317 | G12: =F12 -> 45317 | H12: =G12 -> 45317 | I12: Referido Outbound | J12: margareth.arias@bold.co | K12: 200000000 | L12: 2.05 | Q12: =VLOOKUP(C12,QS!E:AB,21,0) -> #REF! | R12: =VLOOKUP(C12,QS!E:AB,22,0) -> #REF! | S12: =VLOOKUP(C12,QS!E:AB,23,0) -> #REF! | T12: =VLOOKUP(C12,QS!E:AB,24,0) -> #REF!
A13: luis.corredor@bold.co | B13: CASSARENA | C13: W06BXLMD3C | D13: Si | E13: =TEXT(F13, "mmmm yyyy") -> enero 2024 | F13: 45318 | G13: =F13 -> 45318 | H13: =G13 -> 45318 | I13: SI | J13: andres.cardozo@bold.co | K13: 100000000 | L13: 2,19+300 | P13: Si | Q13: =VLOOKUP(C13,QS!E:AB,21,0) -> #REF! | R13: =VLOOKUP(C13,QS!E:AB,22,0) -> #REF! | S13: =VLOOKUP(C13,QS!E:AB,23,0) -> #REF! | T13: =VLOOKUP(C13,QS!E:AB,24,0) -> #REF!
A14: jhonatan.moreno@bold.co | B14: ALFAPARF | C14: VOG2HUW5VO | D14: Si | E14: =TEXT(F14, "mmmm yyyy") -> febrero 2024 | F14: 45323 | G14: =F14 -> 45323 | H14: =G14 -> 45323 | I14: Cliente Propio | K14: 250000000 | L14: 2,19+$300 | Q14: =VLOOKUP(C14,QS!E:AB,21,0) -> #REF! | R14: =VLOOKUP(C14,QS!E:AB,22,0) -> #REF! | S14: =VLOOKUP(C14,QS!E:AB,23,0) -> #REF! | T14: =VLOOKUP(C14,QS!E:AB,24,0) -> #REF!
A15: jhonatan.moreno@bold.co | B15: Surubi Food | C15: VIFU5YJBTM | D15: Si | E15: =TEXT(F15, "mmmm yyyy") -> febrero 2024 | F15: 45324 | G15: =F15 -> 45324 | H15: =G15 -> 45324 | I15: Referido Outbound | J15: jaime.barrios@bold.co | K15: 100000000 | L15: 2,19+$300 | P15: Si | Q15: =VLOOKUP(C15,QS!E:AB,21,0) -> #REF! | R15: =VLOOKUP(C15,QS!E:AB,22,0) -> #REF! | S15: =VLOOKUP(C15,QS!E:AB,23,0) -> #REF! | T15: =VLOOKUP(C15,QS!E:AB,24,0) -> #REF!
A16: luis.corredor@bold.co | B16: Miguel Burger | C16: DQDQKMENXA | D16: Si | E16: =TEXT(F16, "mmmm yyyy") -> febrero 2024 | F16: 45324 | G16: =F16 -> 45324 | H16: =G16 -> 45324 | I16: No | K16: 160000000 | L16: 2,09+$100 | P16: Si | Q16: =VLOOKUP(C16,QS!E:AB,21,0) -> #REF! | R16: =VLOOKUP(C16,QS!E:AB,22,0) -> #REF! | S16: =VLOOKUP(C16,QS!E:AB,23,0) -> #REF! | T16: =VLOOKUP(C16,QS!E:AB,24,0) -> #REF!
A17: angel.lesmes@bold.co | B17: Restaurante Musashi | C17: QKCESKPA91 | D17: Si | E17: =TEXT(F17, "mmmm yyyy") -> febrero 2024 | F17: 45336 | G17: =F17 -> 45336 | H17: =G17 -> 45336 | I17: No | K17: 20000000 | L17: 2,19% + $300 | P17: Pendientes | Q17: =VLOOKUP(C17,QS!E:AB,21,0) -> #REF! | R17: =VLOOKUP(C17,QS!E:AB,22,0) -> #REF! | S17: =VLOOKUP(C17,QS!E:AB,23,0) -> #REF! | T17: =VLOOKUP(C17,QS!E:AB,24,0) -> #REF!
A18: angel.lesmes@bold.co | B18: Restaurante Musashi | C18: YE6RMJFK6K | D18: Si | E18: =TEXT(F18, "mmmm yyyy") -> febrero 2024 | F18: 45336 | G18: =F18 -> 45336 | H18: =G18 -> 45336 | I18: No | K18: 20000000 | L18: 2,19% + $300 | P18: Pendientes | Q18: =VLOOKUP(C18,QS!E:AB,21,0) -> #REF! | R18: =VLOOKUP(C18,QS!E:AB,22,0) -> #REF! | S18: =VLOOKUP(C18,QS!E:AB,23,0) -> #REF! | T18: =VLOOKUP(C18,QS!E:AB,24,0) -> #REF!
A19: jhonatan.torres@bold.co | B19: Artesanal | C19: YEY17SS4UP | D19: Si | E19: =TEXT(F19, "mmmm yyyy") -> febrero 2024 | F19: 45336 | G19: =F19 -> 45336 | H19: =G19 -> 45336 | I19: Referido Outbound | J19: luis.correa@bold.co | K19: 100000000 | L19: 2,19% + $300 | Q19: =VLOOKUP(C19,QS!E:AB,21,0) -> #REF! | R19: =VLOOKUP(C19,QS!E:AB,22,0) -> #REF! | S19: =VLOOKUP(C19,QS!E:AB,23,0) -> #REF! | T19: =VLOOKUP(C19,QS!E:AB,24,0) -> #REF!
A20: angel.lesmes@bold.co | B20: Almacén Y Taller Todo Nissan Ayt Sas | C20: VTCXH9AYXO | D20: Si | E20: =TEXT(F20, "mmmm yyyy") -> febrero 2024 | F20: 45337 | G20: =F20 -> 45337 | H20: =G20 -> 45337 | I20: Cliente Propio | K20: 50000000 | L20: 2,19% + $300 | P20: Pendientes | Q20: =VLOOKUP(C20,QS!E:AB,21,0) -> #REF! | R20: =VLOOKUP(C20,QS!E:AB,22,0) -> #REF! | S20: =VLOOKUP(C20,QS!E:AB,23,0) -> #REF! | T20: =VLOOKUP(C20,QS!E:AB,24,0) -> #REF!
A21: cristian.baquero@bold.co | B21: Acabados dyp | C21: CGTPT8L3DG | D21: Si | E21: =TEXT(F21, "mmmm yyyy") -> febrero 2024 | F21: 45332 | G21: =F21 -> 45332 | H21: =G21 -> 45332 | I21: Cliente Propio | K21: 30000000 | L21: 2,19% + $300 | Q21: =VLOOKUP(C21,QS!E:AB,21,0) -> #REF! | R21: =VLOOKUP(C21,QS!E:AB,22,0) -> #REF! | S21: =VLOOKUP(C21,QS!E:AB,23,0) -> #REF! | T21: =VLOOKUP(C21,QS!E:AB,24,0) -> #REF!
A22: cristian.baquero@bold.co | B22: Dukari | C22: CBL16SJULR | D22: Si | E22: =TEXT(F22, "mmmm yyyy") -> febrero 2024 | F22: 45334 | G22: =F22 -> 45334 | H22: =G22 -> 45334 | I22: Cliente Propio | K22: 50000000 | L22: 2,59% + $900 (solo Link) | Q22: 482000 | R22: =VLOOKUP(C22,QS!E:AB,22,0) -> #REF! | S22: =VLOOKUP(C22,QS!E:AB,23,0) -> #REF! | T22: =VLOOKUP(C22,QS!E:AB,24,0) -> #REF!
A23: cristian.baquero@bold.co | B23: Lebog | C23: EO5ZB49DG2 | D23: Si | E23: =TEXT(F23, "mmmm yyyy") -> febrero 2024 | F23: 45336 | G23: =F23 -> 45336 | H23: =G23 -> 45336 | I23: Cliente Propio | K23: 50000000 | L23: 2,19% + $300 | Q23: =VLOOKUP(C23,QS!E:AB,21,0) -> #REF! | R23: =VLOOKUP(C23,QS!E:AB,22,0) -> #REF! | S23: =VLOOKUP(C23,QS!E:AB,23,0) -> #REF! | T23: =VLOOKUP(C23,QS!E:AB,24,0) -> #REF!
A24: cristian.baquero@bold.co | B24: Foodology | C24: OFC2I4Z2PO | D24: Si | E24: =TEXT(F24, "mmmm yyyy") -> febrero 2024 | F24: 45342 | G24: =F24 -> 45342 | H24: =G24 -> 45342 | I24: Referido Outbound | J24: cristian.casas@bold.co | K24: 600000000 | L24: 0.0199 | P24: Pendientes | Q24: =VLOOKUP(C24,QS!E:AB,21,0) -> #REF! | R24: =VLOOKUP(C24,QS!E:AB,22,0) -> #REF! | S24: =VLOOKUP(C24,QS!E:AB,23,0) -> #REF! | T24: =VLOOKUP(C24,QS!E:AB,24,0) -> #REF!
A25: angel.lesmes@bold.co | B25: Medina Golden | C25: DUJE9XZH3Q | D25: Si | E25: =TEXT(F25, "mmmm yyyy") -> febrero 2024 | F25: 45345 | G25: =F25 -> 45345 | H25: =G25 -> 45345 | I25: Cliente Propio | K25: 100000000 | L25: 1.99 | P25: Pendientes | Q25: =VLOOKUP(C25,QS!E:AB,21,0) -> #REF! | R25: =VLOOKUP(C25,QS!E:AB,22,0) -> #REF! | S25: =VLOOKUP(C25,QS!E:AB,23,0) -> #REF! | T25: =VLOOKUP(C25,QS!E:AB,24,0) -> #REF!
A26: luis.corredor@bold.co | B26: Beef PuraRaza | C26: NY6646ULTO | D26: Si | E26: =TEXT(F26, "mmmm yyyy") -> febrero 2024 | F26: 45345 | G26: =F26 -> 45345 | H26: =G26 -> 45345 | I26: Referido Spiders | J26: angie.rodriguez@bold.co | K26: 150000000 | L26: 2,09+$100 | P26: Si | Q26: =VLOOKUP(C26,QS!E:AB,21,0) -> #REF! | R26: =VLOOKUP(C26,QS!E:AB,22,0) -> #REF! | S26: =VLOOKUP(C26,QS!E:AB,23,0) -> #REF! | T26: =VLOOKUP(C26,QS!E:AB,24,0) -> #REF!
A27: jhonatan.moreno@bold.co | B27: LA FINCA DE RIGOLLANOGRANDE | C27: 1AG1WY7CSP | D27: Si | E27: =TEXT(F27, "mmmm yyyy") -> marzo 2024 | F27: 45352 | G27: =F27 -> 45352 | H27: =G27 -> 45352 | I27: Referido Spiders | J27: angie.rodriguez@bold.co | K27: 200000000 | P27: Pendientes
A28: jhonatan.moreno@bold.co | B28: GO RIGO GO PALMAS | C28: 3F86R9UN91 | D28: Si | E28: =TEXT(F28, "mmmm yyyy") -> marzo 2024 | F28: 45352 | G28: =F28 -> 45352 | H28: =G28 -> 45352 | I28: Referido Spiders | J28: sandra.robayo@bold.co | K28: 200000000 | P28: Pendientes
A29: luis.corredor@bold.co | B29: Zona cafe y pan | C29: C2T5G954F1 | D29: Si | E29: =TEXT(F29, "mmmm yyyy") -> marzo 2024 | F29: 45352 | G29: =F29 -> 45352 | H29: =G29 -> 45352 | I29: Referido Spiders | J29: nazareth.ruiz@bold.co | K29: 40000000 | L29: 2,19% + $300
A30: angel.lesmes@bold.co | B30: Mi Tierra | C30: T0EM6PSD79 | D30: Si | E30: =TEXT(F30, "mmmm yyyy") -> marzo 2024 | F30: 45352 | G30: =F30 -> 45352 | H30: =G30 -> 45352 | I30: Referido Spiders | J30: milton.ortiz@bold.co | K30: 50000000 | L30: 2,19% + $300
A31: jhonatan.moreno@bold.co | B31: GRACIES | C31: PQFEX2AY4O | D31: Si | E31: =TEXT(F31, "mmmm yyyy") -> marzo 2024 | F31: 45355 | G31: =F31 -> 45355 | H31: =G31 -> 45355 | I31: Cliente Propio | K31: 80000000 | L31: 2.19
A32: jhonatan.moreno@bold.co | B32: COLTOLIMA | C32: KUQFCYOJ5F | D32: Si | E32: =TEXT(F32, "mmmm yyyy") -> marzo 2024 | F32: 45355 | G32: =F32 -> 45355 | H32: =G32 -> 45355 | I32: Cliente Propio | P32: Pendientes
A33: luis.corredor@bold.co | B33: Veolia Archipiélago sas esp | C33: YO5Y2NTPRY | D33: Si | E33: =TEXT(F33, "mmmm yyyy") -> marzo 2024 | F33: 45355 | G33: =F33 -> 45355 | H33: =G33 -> 45355 | I33: Referido Outbound | J33: edwar.sinisterra@bold.co | K33: 150000000 | L33: 2.19 | P33: Revision
A34: cristian.baquero@bold.co | B34: Rosalba Sanchez | C34: 1MEOXAZD4L | D34: Si | E34: =TEXT(F34, "mmmm yyyy") -> marzo 2024 | F34: 45356 | G34: =F34 -> 45356 | H34: =G34 -> 45356 | I34: Referido Spiders | J34: angie.rodriguez@bold.co | K34: 80000000 | L34: 2,19 + $300 | P34: Pendientes
A35: cristian.baquero@bold.co | B35: VFS Colombia SAS | C35: W522Q392Y7 | D35: Si | E35: =TEXT(F35, "mmmm yyyy") -> marzo 2024 | F35: 45356 | G35: =F35 -> 45356 | H35: =G35 -> 45356 | I35: Referido Spiders | J35: milton.ortiz@bold.co | K35: 400000000 | L35: 0.0199 | P35: Pendientes
A36: cristian.baquero@bold.co | B36: VFS Colombia SAS | C36: PZKOSYJEEO | D36: Si | E36: =TEXT(F36, "mmmm yyyy") -> marzo 2024 | F36: 45356 | G36: =F36 -> 45356 | H36: =G36 -> 45356 | I36: Referido Spiders | J36: milton.ortiz@bold.co | K36: 400000000 | L36: 0.0199 | P36: Pendientes
A37: cristian.baquero@bold.co | B37: VFS Colombia SAS | C37: W636X85VHW | D37: Si | E37: =TEXT(F37, "mmmm yyyy") -> marzo 2024 | F37: 45356 | G37: =F37 -> 45356 | H37: =G37 -> 45356 | I37: Referido Spiders | J37: milton.ortiz@bold.co | K37: 400000000 | L37: 0.0199 | P37: Pendientes
A38: jhonatan.moreno@bold.co | B38: German Summa | C38: 0NAMJ65HII | D38: Si | E38: =TEXT(F38, "mmmm yyyy") -> marzo 2024 | F38: 45363 | G38: =F38 -> 45363 | H38: =G38 -> 45363 | I38: Cliente Propio | K38: 40000000
A39: luis.corredor@bold.co | B39: Combos cosmicos portal 80 | C39: OFZJDWZPTJ | D39: Si | E39: =TEXT(F39, "mmmm yyyy") -> marzo 2024 | F39: 45363 | G39: =F39 -> 45363 | H39: =G39 -> 45363 | I39: Cliente Propio | K39: 30000000 | L39: 2,19 + $300
A40: jhonatan.moreno@bold.co | B40: Atractiva Calzados | C40: TP4LNEUN1M | D40: Si | E40: =TEXT(F40, "mmmm yyyy") -> marzo 2024 | F40: 45365 | G40: =F40 -> 45365 | H40: =G40 -> 45365 | I40: Cliente Propio | K40: 30000000 | L40: 2,19 + $300
...

Sheet CLIENTES A, nuevos
A1: Ejecutivo | B1: Nombre Cliente | C1: Merchant ID | D1: Creado en CRM | E1: Mes Año | F1: Fecha de activacion | G1: Mes | H1: Año | I1: ORIGEN del Cliente | J1: Si es referido Correo electronico De quien refiere de no ser asi dejar N/A | K1: TPV Potencial en MIllones | L1: Tarifa Aplicada | M1: DATAFONOS | N1: QR-LINK-BOTON | O1: CONTRATOS FRAUDE | P1: CONTRATOS | Q1: TPV M0 | R1: TPV M1 | S1: TPV M2 | T1: TPV M3 | U1: PROMEDIO TPV | V1: Formato entrega de comercios | W1: KAM que recibe Comercio

Sheet ESCALAMIENTOS GRAL
A1: Área | B1: Custodio | C1: Nombre cliente | E1: Merchant | F1: Fecha incidente | G1: Mes | H1: Año | I1: Fecha de reporte | J1: Incidente | K1: Encargado | L1: Fecha solución | M1: Valor | N1: Observación | O1: Estado | P1: Categoria
A2: Producto pagos | B2: C. Camilo Casas | C2: POSTOBON | D2: Postobon | E2: UKH72XS44S | F2: 46028 | G2: ENERO | H2: =YEAR(F2) -> 2026 | I2: 46028 | J2: TX rechazadas | K2: Leidy Rodriguez Raul Navarrete | L2: 02/20/2026 | M2: 342700 | N2: PENDIENTE CERTIFICADO DE COBRO | O2: Resuelto | P2: Pagos rechazados/no abonados/descontados
A3: MKT | B3: Juan Camilo Salgado | C3: POSTOBON | D3: Postobon | E3: -- | F3: 46042 | G3: ENERO | H3: =YEAR(F3) -> 2026 | I3: 46042 | J3: Peticion | K3: Laura Londoño | L3: -- | M3: 0 | N3: Peticion de Pieza grafica para incentivar recudo digital. | O3: Pendiente | P3: Solicitud pieza grafica
A4: Producto pagos | B4: C. Camilo Casas | C4: POSTOBON | D4: Postobon | E4: UKH72XS44S | F4: 46039 | G4: ENERO | H4: =YEAR(F4) -> 2026 | I4: 46045 | J4: TX rechazadas | K4: Leidy Rodriguez | L4: -- | M4: 391458 | N4: /después de validar la transacción T4RRHIMENLZ por valor de $391.458 del pasado 17/01/2026, te confirmamos que no tenemos abono en nuestra cuenta. Como muestra en tu aplicación, la transacción no fue exitosa. En el caso de que tu cliente final insista en que tiene el descuento, es necesario que él o ella solicite a su banco un certificado del cobro de esta misma con fecha posterior al 27/01/2026 para poder escalar el caso con la entidad financiera. | O4: Pendiente | P4: Pagos rechazados/no abonados/descontados
A5: Producto pagos | B5: C. Camilo Casas | C5: POSTOBON | D5: Postobon | E5: UKH72XS44S | F5: 46028 | G5: ENERO | H5: =YEAR(F5) -> 2026 | I5: 46045 | J5: TX rechazadas | K5: Incidencias | L5: 46049 | M5: 442250 | N5: después de validar la transacción TOB09WUQ3T3 por valor de $442.250 del pasado 06/01/2026, te confirmamos que sí tenemos un abono. Hoy se solicitó un cambio de estado y podrás ver la modificación desde tu aplicación, así como el abono de la venta, en 1 día hábil en tu Saldo de Ventas Bold. | O5: Resuelto | P5: Pagos rechazados/no abonados/descontados
A6: Producto pagos | B6: C. Camilo Casas | C6: POSTOBON | D6: Postobon | E6: QBLW9W0FGB | F6: 45973 | G6: NOVIEMBRE | H6: =YEAR(F6) -> 2025 | I6: 46055 | J6: TX rechazadas | K6: Incidencias | M6: 762500 | N6: PENDIENTE CERTIFICADO DE COBRO | O6: Resuelto
A7: Producto pagos | B7: C. Camilo Casas | C7: POSTOBON | D7: Postobon | E7: QBLW9W0FGB | F7: 45997 | G7: DICIEMBRE | H7: =YEAR(F7) -> 2025 | I7: 46055 | J7: TX rechazadas | K7: Incidencias | M7: 526100 | N7: PENDIENTE CERTIFICADO DE COBRO / y info deTRX | O7: Resuelto
A8: Producto pagos | B8: C. Camilo Casas | C8: POSTOBON | D8: Postobon | E8: QBLW9W0FGB | F8: 45997 | G8: DICIEMBRE | H8: =YEAR(F8) -> 2025 | I8: 46055 | J8: TX rechazadas | K8: Incidencias | M8: 1505300 | N8: PENDIENTE CERTIFICADO DE COBRO / y info deTRX | O8: Resuelto
A9: Producto pagos | B9: C. Camilo Casas | C9: POSTOBON | D9: Postobon | E9: QBLW9W0FGB | F9: 45677 | G9: ENERO | H9: =YEAR(F9) -> 2025 | I9: 46045 | J9: TX rechazadas | K9: Leidy Rodriguez | L9: 46050 | M9: 495000 | N9: te confirmamos que sí tenemos un abono. Hoy 29 de enero se solicitó un cambio de estado y podrás ver la modificación desde tu aplicación, así como el abono de la venta, en 1 día hábil en tu Saldo de Ventas Bold. | O9: Resuelto | P9: Pagos rechazados/no abonados/descontados
A10: Producto pagos | B10: C. Camilo Casas | C10: POSTOBON | D10: Postobon | E10: UKH72XS44S | F10: 45987 | G10: NOVIEMBRE | H10: =YEAR(F10) -> 2025 | I10: 46075 | J10: TX rechazadas | K10: Leidy Rodriguez | L10: 46050 | M10: 300000 | N10: consignación entre cuentas ACH 7 Linda lamentamos las molestias generadas, te confirmamos que en efecto la transferencia dispersada por $1.882.032,00 el 18 de diciembre 2025 que ingreso a tu cuenta el 22 de diciembre del 2025 se compone de las transacciones TCXESFK250I, T0YGLC83436, TXN10CNJM2Q. | O10: Resuelto
A11: Producto cuenta | B11: Jeyson Salazar | C11: Coopicredito | D11: Coopicredito | E11: NAKCEJYG9R | F11: 46044 | G11: ENERO | H11: =YEAR(F11) -> 2026 | I11: 46044 | J11: Cuenta Bold | K11: Jesus Marrugo | M11: -- | N11: Cliente al intentar crear un usuario de consultas en su Cuenta Bold, arroja un error, está en revisión por parte del equipo de Banking | O11: Resuelto
A12: Producto pagos | B12: Jeyson Salazar | C12: Coopicredito | D12: Coopicredito | E12: CJZ9L7O0SB | F12: 46042 | G12: ENERO | H12: =YEAR(F12) -> 2026 | I12: 46042 | J12: Falla QR | K12: Carlos Manrique | M12: -- | N12: Se evidencia que las txs por QR no le estamos cobrando la comisión, es una falla en la API de Pagos, Producto está revisando la solución pronta. | O12: Resuelto
A13: Tecnologia | B13: Jeyson Salazar | C13: Coopicredito | D13: Coopicredito | E13: CJZ9L7O0SB | F13: 46042 | G13: ENERO | H13: =YEAR(F13) -> 2026 | I13: 46042 | J13: Solicitudes a Producto | K13: Lina Toquica | M13: -- | N13: Se evidencia diferencias en la longitud de caracteres en el campo "REALIZADO POR" de la estructura de Cierre de Turno, está ciendo revisada por el equipo de TI. | O13: Resuelto
A14: Producto pagos | B14: C. Camilo Casas | C14: POSTOBON | D14: Postobon | E14: UKH72XS44S | F14: 46042 | G14: ENERO | H14: =YEAR(F14) -> 2026 | I14: 132800 | J14: TX rechazadas | K14: Leidy Rodriguez | L14: 46030 | M14: 915000 | N14: después de validar la transacción TW4G4MSHDCK por valor de $915.000 del pasado 20/01/2026, te confirmamos que sí tenemos un abono. Hoy se solicitó un cambio de estado y podrás ver la modificación desde tu aplicación, así como el abono de la venta, en 1 día hábil en tu Saldo de Ventas Bold. | O14: Resuelto | P14: Pagos rechazados/no abonados/descontados
A15: Producto pagos | B15: C. Camilo Casas | C15: POSTOBON | D15: Postobon | E15: UKH72XS44S | F15: 46044 | G15: ENERO | H15: =YEAR(F15) -> 2026 | I15: 132800 | J15: Falla QR | K15: Bayron Romero | L15: 45680 | M15: -- | N15: QR presenta novedad se coloca valor X aparece otro valor en el app del cliente al momento de scanear usuario salo0520sebas@gmail.com | O15: Resuelto | P15: Problemas de plataforma
A16: Producto pagos | B16: C. Camilo Casas | C16: POSTOBON | D16: Postobon | E16: SE3RYFGAJY | F16: 46042 | G16: ENERO | H16: =YEAR(F16) -> 2026 | I16: 46045 | J16: TX rechazadas | K16: Leidy Rodriguez | L16: 46050 | M16: 1658000 | N16: después de validar la transacción TRRNTDA5IQ5 por valor de $1.658.000 del pasado 20/01/2026, te confirmamos que sí tenemos un abono. Hoy se solicitó un cambio de estado y podrás ver la modificación desde tu aplicación, así como el abono de la venta, en 1 día hábil en tu Saldo de Ventas Bold. | O16: Resuelto | P16: Pagos rechazados/no abonados/descontados
A17: Producto pagos | B17: C. Camilo Casas | C17: POSTOBON | D17: Postobon | E17: SE3RYFGAJY | F17: 46042 | G17: ENERO | H17: =YEAR(F17) -> 2026 | I17: 46045 | J17: TX rechazadas | K17: Leidy Rodriguez | L17: 46050 | M17: 245000 | N17: después de validar la transacción TSQN2T5WZFI por valor de $245.000 del pasado 20/01/2026, te confirmamos que sí tenemos un abono. Hoy se solicitó un cambio de estado y podrás ver la modificación desde tu aplicación, así como el abono de la venta, en 1 día hábil en tu Saldo de Ventas Bold. | O17: Resuelto | P17: Pagos rechazados/no abonados/descontados
A18: Producto pagos | B18: C. Camilo Casas | C18: POSTOBON | D18: Postobon | E18: DKFDV7RLFX | F18: 46042 | G18: ENERO | H18: =YEAR(F18) -> 2026 | I18: 46045 | J18: TX rechazadas | K18: Leidy Rodriguez | L18: 46049 | M18: 2315000 | N18: después de validar la transacción TJ5OTA5TFIR por valor de $2.315.000 del pasado 20/01/2026, te confirmamos que sí tenemos un abono. Hoy se solicitó un cambio de estado y podrás ver la modificación desde tu aplicación, así como el abono de la venta, en 1 día hábil en tu Saldo de Ventas Bold. | O18: Resuelto | P18: Pagos rechazados/no abonados/descontados
A19: Producto pagos | B19: C. Camilo Casas | C19: POSTOBON | D19: Postobon | E19: DKFDV7RLFX | F19: 46042 | G19: ENERO | H19: =YEAR(F19) -> 2026 | I19: 46045 | J19: TX rechazadas | K19: Leidy Rodriguez | L19: -- | M19: 1960300 | N19: PENDIENTE CERTIFICADO DE COBRO / ID TRANSACCIÓN | O19: Pendiente | P19: Pagos rechazados/no abonados/descontados
A20: Producto pagos | B20: C. Camilo Casas | C20: POSTOBON | D20: Postobon | E20: DKFDV7RLFX | F20: 46042 | G20: ENERO | H20: =YEAR(F20) -> 2026 | I20: 46045 | J20: TX rechazadas | K20: Leidy Rodriguez | L20: 46049 | M20: 101100 | N20: después de validar la transacción TC6H5UF8V7B por valor de $101.100 del pasado 20/01/2026, te confirmamos que sí tenemos un abono. Hoy se solicitó un cambio de estado y podrás ver la modificación desde tu aplicación, así como el abono de la venta, en 1 día hábil en tu Saldo de Ventas Bold. | O20: Resuelto | P20: Pagos rechazados/no abonados/descontados
A21: Producto pagos | B21: C. Camilo Casas | C21: POSTOBON | D21: Postobon | E21: SE3RYFGAJY | F21: 46037 | G21: ENERO | H21: =YEAR(F21) -> 2026 | I21: 46045 | J21: TX rechazadas | K21: Leidy Rodriguez | L21: 46050 | M21: 155100 | N21: después de validar la transacción TPN2EQAQ91K por valor de $155.100 del pasado 15/01/2026, te confirmamos que sí tenemos un abono. Hoy se solicitó un cambio de estado y podrás ver la modificación desde tu aplicación, así como el abono de la venta, en 1 día hábil en tu Saldo de Ventas Bold. | O21: Resuelto | P21: Pagos rechazados/no abonados/descontados
A22: Producto pagos | B22: C. Camilo Casas | C22: POSTOBON | D22: Postobon | E22: Z2LOEMM4GD | F22: 46022 | G22: =TEXT(F22,"mmmm") -> diciembre | H22: =YEAR(F22) -> 2025 | I22: 46045 | J22: TX rechazadas | K22: Leidy Rodriguez | L22: 46049 | M22: 1274749 | N22: Respecto a la consulta realizada el día 23/01/2026, te comentamos que para el comercio Z2LOEMM4GD no se logra localizar una transacción por valor de $1.274.749 del pasado 31/12/2025 tal como muestra el comprobante enviado. Agradecemos nos envíes el ID de la transacción, adicionalmente en el caso de que tu cliente final insista en que tiene el descuento, es necesario que él o ella solicite a su banco un certificado del cobro de esta misma con fecha posterior al 27/01/2026 para poder escalar el caso con la entidad financiera. | O22: Pendiente | P22: Pagos rechazados/no abonados/descontados
A23: Producto pagos | B23: C. Camilo Casas | C23: POSTOBON | D23: Postobon | E23: Q7VR1248VT | F23: 46044 | G23: DICEMBRE | H23: =YEAR(F23) -> 2026 | I23: 46045 | J23: Error ingreso App | K23: Bayron Steven | L23: 46047 | M23: -- | N23: Transportador: App no le permite el ingreso correctamente | O23: Pendiente | P23: Errores o Fallas cuenta BOLD
A24: Producto pagos | B24: C. Camilo Casas | C24: POSTOBON | D24: Postobon | E24: TOM95X6WAO | F24: 46042 | G24: ENERO | H24: =YEAR(F24) -> 2026 | I24: 46045 | J24: TX rechazadas | K24: Leidy Rodriguez | L24: 46049 | M24: 249900 | N24: después de validar la transacción TYK4V5G3OL7 por valor de $249.900 del pasado 20/01/2026, te confirmamos que sí tenemos un abono. Hoy se solicitó un cambio de estado y podrás ver la modificación desde tu aplicación, así como el abono de la venta, en 1 día hábil en tu Saldo de Ventas Bold. | O24: Resuelto | P24: Pagos rechazados/no abonados/descontados
A25: Producto pagos | B25: C. Camilo Casas | C25: POSTOBON | D25: Postobon | E25: QBLW9W0FGB | F25: 45965 | G25: NOVIEMBRE | H25: =YEAR(F25) -> 2025 | I25: 45965 | J25: TX rechazadas | K25: Bayron Romero | M25: 780000 | N25: Canal de escalamiento informa que sin certificado de cobro logran encontrar TRX revisar link de Slack | O25: Pendiente | P25: Pagos rechazados/no abonados/descontados
A26: Producto pagos | B26: C. Camilo Casas | C26: POSTOBON | D26: Postobon | E26: DKFDV7RLFX | F26: 46049 | G26: ENERO | H26: =YEAR(F26) -> 2026 | I26: 46049 | J26: TX rechazadas | K26: Leidy rogriguez | L26: 46049 | M26: 1488032 | N26: Se reversa transacción al pagador | O26: Resuelto | P26: Pagos rechazados/no abonados/descontados
A27: Producto pagos | B27: C. Camilo Casas | C27: Colanta | D27: Colanta | E27: VY6VES3Z9R | F27: 46062 | G27: FEBRERO | H27: =YEAR(F27) -> 2026 | I27: 46071 | J27: TX rechazadas | K27: Leidy Rodriguez | L27: 46072 | M27: 86402 | N27: se cambia de estado TRX y se abona el dinero el dia 20 de febrero al cuenta | O27: Resuelto | P27: Pagos rechazados/no abonados/descontados
A28: Producto pagos | B28: C. Camilo Giraldo | C28: POSTOBON | D28: Postobon | E28: TOM95X6WAO | F28: 46065 | G28: FEBRERO | H28: =YEAR(F28) -> 2026 | I28: 46072 | J28: TX rechazadas | K28: incidencias | L28: 46072 | M28: 1445124 | N28: la transacción no fue exitosa. En el caso de que tu cliente final insista en que tiene el descuento, es necesario que él o ella solicite a su banco un certificado del cobro de esta misma con fecha posterior al 19/02/2026 para poder escalar el caso con la entidad financiera. | O28: Pendiente | P28: Pagos rechazados/no abonados/descontados
A29: Producto pagos | B29: C. Camilo Casas | C29: Colanta | D29: Colanta | E29: VY6VES3Z9R | F29: 46062 | G29: FEBRERO | H29: =YEAR(F29) -> 2026 | I29: 46071 | J29: TX rechazadas | K29: Leidy Rodriguez | L29: 46072 | M29: 240668 | N29: ya encontraron el abono. El 19 de febrero se cambia el estado y 20 Febrero se abona dinero cuenta COLANTA | O29: Resuelto | P29: Pagos rechazados/no abonados/descontados
A30: Producto pagos | B30: C. Camilo Giraldo | C30: POSTOBON | D30: Postobon | E30: UKH72XS44S | F30: 46062 | G30: FEBRERO | H30: =YEAR(F30) -> 2026 | I30: 46072 | J30: TX rechazadas | K30: incidencias | L30: 46072 | M30: 1701800 | N30: Hoy se solicitó un cambio de estado y podrás ver la modificación desde tu aplicación, así como el abono de la venta, en 1 día hábil en tu Saldo de Ventas Bold. | O30: Resuelto | P30: Pagos rechazados/no abonados/descontados
A31: Producto pagos | B31: C. Camilo Casas | C31: Colanta | D31: Colanta | E31: VY6VES3Z9R | F31: 46056 | G31: FEBRERO | H31: =YEAR(F31) -> 2026 | I31: 46064 | J31: TX rechazadas | K31: Leidy Rodriguez | M31: 343495 | N31: transferencia interbancaria | O31: Pendiente | P31: Pagos rechazados/no abonados/descontados
A32: Producto pagos | B32: C. Camilo Giraldo | C32: POSTOBON | D32: Postobon | E32: UKH72XS44S | F32: 46056 | G32: FEBRERO | H32: =YEAR(F32) -> 2026 | I32: 46072 | J32: TX rechazadas | K32: Incidencias | L32: 46072 | M32: 586600 | N32: te confirmamos que sí tenemos un abono. Hoy se solicitó un cambio de estado y podrás ver la modificación desde tu aplicación, así como el abono de la venta, en 1 día hábil en tu Saldo de Ventas Bold. | O32: Resuelto | P32: Pagos rechazados/no abonados/descontados
A33: Producto pagos | B33: C. Camilo Giraldo | C33: POSTOBON | D33: Postobon | E33: UKH72XS44S | F33: 46062 | G33: FEBRERO | H33: =YEAR(F33) -> 2026 | I33: 46072 | J33: TX rechazadas | K33: Incidencias | L33: 46072 | M33: 360300 | N33: te confirmamos que sí tenemos un abono. Hoy se solicitó un cambio de estado y podrás ver la modificación desde tu aplicación, así como el abono de la venta, en 1 día hábil en tu Saldo de Ventas Bold. | O33: Resuelto | P33: Pagos rechazados/no abonados/descontados
A34: Producto pagos | B34: C. Camilo Giraldo | C34: POSTOBON | D34: Postobon | E34: UKH72XS44S | F34: 46063 | G34: FEBRERO | H34: =YEAR(F34) -> 2026 | I34: 46072 | J34: TX rechazadas | K34: Incidencias | L34: 46072 | M34: 519000 | N34: te confirmamos que sí tenemos un abono. Hoy se solicitó un cambio de estado y podrás ver la modificación desde tu aplicación, así como el abono de la venta, en 1 día hábil en tu Saldo de Ventas Bold. | O34: Resuelto | P34: Pagos rechazados/no abonados/descontados
A35: Producto pagos | B35: C. Camilo Casas | C35: POSTOBON | D35: Postobon | E35: SE3RYFGAJY | F35: 46191 | G35: JUNIO | H35: =YEAR(F35) -> 2026 | I35: 46072 | J35: TX rechazadas | K35: Leidy rodriguez | L35: 46072 | M35: 95500 | N35: Hoy se solicitó un cambio de estado y podrás ver la modificación desde tu aplicación, así como el abono de la venta, en 1 día hábil en tu Saldo de Ventas Bold. | O35: Resuelto | P35: Pagos rechazados/no abonados/descontados
A36: Producto pagos | B36: C. Camilo Casas | C36: Colanta | D36: Colanta | E36: VY6VES3Z9R | F36: 46297 | G36: OCTUBRE | H36: =YEAR(F36) -> 2026 | I36: 46072 | J36: TX rechazadas | K36: Leidy rodriguez | L36: 46077 | M36: 173230 | N36: se encuentra transacción consignada por llave | O36: Resuelto | P36: Pagos rechazados/no abonados/descontados
A38: Producto pagos | B38: C. Camilo Casas | C38: POSTOBON | D38: Postobon | E38: CPKYDJ4IMOIJ | F38: 46108 | G38: MARZO | H38: 2026 | I38: 46111 | J38: TX rechazadas | K38: Leidy rodriguez | L38: 46118 | M38: 331200 | N38: sapena@postobon.com.co -te confirmamos que no tenemos abono en nuestra cuenta. Como muestra en tu aplicación, la transacción no fue exitosa. En el caso de que tu cliente final insista en que tiene el descuento, es necesario que él o ella solicite a su banco un certificado del cobro de esta misma con fecha posterior al 06/04/2026 para poder escalar el caso con la entidad financiera. | O38: Falta certificado | P38: Pagos rechazados/no abonados/descontados
A39: Producto pagos | B39: C. Camilo Giraldo | C39: POSTOBON | D39: Postobon | E39: TOM95X6WAO | F39: 46106 | G39: ABRIL | H39: 2026 | I39: 46113 | J39: TX rechazadas | K39: Leidy rodriguez | L39: 46119 | M39: 800000 | N39: aliviafara9@gmail.com Respecto a tu consulta realizada el día 01/04/2026, después de validar la transacción TAVTEU2H6OY por valor de $800.000 del pasado 25/03/2026, te confirmamos que sí tenemos un abono. Hoy se solicitó un cambio de estado y podrás ver la modificación desde tu aplicación, así como el abono de la venta, en 1 día hábil en tu Saldo de Ventas Bold. | O39: Resuelto | P39: Pagos rechazados/no abonados/descontados
A40: Producto pagos | B40: C. Camilo Giraldo | C40: POSTOBON | D40: Postobon | E40: 4VETEWDH1L | F40: 46122 | G40: ABRIL | H40: 2026 | I40: 46122 | J40: Payouts no identificados | K40: Camilo Giraldo | L40: 46123 | M40: -- | N40: obocanegra@postobon.com.co Buenas tardes. Con respecto a su consulta sobre los depósitos de los días 09 y 10 de abril, le informo que los pagos ya han sido procesados y enviados desde nuestra plataforma. La demora que se presenta actualmente en la recepción de los fondos se debe a los tiempos de procesamiento de los ciclos de ACH entre las entidades bancarias. Por este motivo, el dinero se verá reflejado en su cuenta de Bancolombia en el transcurso del día, dependiendo de los horarios de compensación de dicha red. te confirmo que los envios fueron realizados a tiempo, pero por los tiempos de transferencia ACH hacia Bancolombia u otros bancos es la novedad presentada. | O40: Resuelto | P40: Otro
A41: Producto pagos | B41: C. Camilo Giraldo | C41: POSTOBON | D41: Postobon | E41: SE3RYFGAJY | F41: 46128 | G41: ABRIL | H41: 2026 | I41: 46134 | J41: TX rechazadas | K41: Leidy rodriguez | L41: 46139 | M41: 113000 | N41: mamaldonado@gascol.com.co: informa que se genero cobro doble por 113.000/R/ Respecto a la consulta realizada el día 23/04/2026, después de validar la transacción TZGPF5VKF1V - TSZA4GMPPVZ - TZ9V0SLX6OB- T0VNHT9FFXT - T56Z25OJ862 - TDFKFEN7ZQT - TLAUMR4XY70 - TQCE6T55C13, cada una por valor de $113.000por medio de pago QR del pasado 16/04/2026, te confirmamos que no tenemos abono en nuestra cuenta. Como muestra en tu aplicación, la transacción no fue exitosa. Adicionalmente, te confirmamos que la transacción con ID: T4D3Z330654 , se encuentra aprobada y fue abonada a la cuenta del comercio. Hola Michel , Respecto a la consulta realizada el día 23/04/2026, después de validar la transacción TZGPF5VKF1V - TSZA4GMPPVZ - TZ9V0SLX6OB- T0VNHT9FFXT - T56Z25OJ862 - TDFKFEN7ZQT - TLAUMR4XY70 - TQCE6T55C13, cada una por valor de $113.000por medio de pago QR del pasado 16/04/2026, te confirmamos que no tenemos abono en nuestra cuenta. Como muestra en tu aplicación, la transacción no fue exitosa. Adicionalmente, te confirmamos que la transacción con ID: T4D3Z330654 , se encuentra aprobada y fue abonada a la cuenta del comercio. En el caso de que tu cliente final insista en que tiene el descuento, es necesario que él o ella solicite a su banco un certificado del cobro de esta misma con fecha posterior al 27/04/2026 para poder escalar el caso con la entidad financiera. | O41: Resuelto | P41: Pagos rechazados/no abonados/descontados
...

Sheet OPERACIONES - MASIVOS
A1: PROYECTO | B1: RAZON SOCIAL | C1: MERCHANT-ID | D1: PRICIN ASIGNADO | E1: IMPUESTOS DesMarcados | F1: QR Agregador ON? | G1: PRODUCTOS OFF | H1: COMENTARIOS-NOVEDAD | I1: NIT | J1: DIRECCION | K1: ENCARGADO | L1: TELEFONO | M1: # CUENTA INSCRITA | N1: IMPLEMENTACION
A2: POSTOBON | B2: GASEOSAS LUX | C2: UKH72XS44S | D2: 0 | E2: Si | F2: Si | G2: Nequi, Efectivo | I2: 860001697 | J2: POSTOBON CALLE 80 BOGOTA / Km 0 + 435 Mts Punta Redonda Vía Siberia / CALLE 80 | K2: MARIA CAMILA ALVAREZ | L2: 3113874244 | M2: 24156243887 / BANCOLOMBIA | N2: LINK-QR
A3: POSTOBON | B3: GASEOSAS LUX | C3: QBLW9W0FGB | D3: 0 | E3: Si | F3: Si | G3: Nequi, Efectivo | I3: 860001697 | J3: PLANTA SEVILLANA BOGOTA LUX SUR | K3: MARIA CAMILA ALVAREZ | L3: 3113874244 | M3: 24500017464 / BANCOLOMBIA | N3: LINK-QR
A4: POSTOBON | B4: GASEOSAS LUX SAS | C4: DKFDV7RLFX | D4: 0 | E4: Si | F4: Si | G4: Nequi, Efectivo | I4: 860001697 | J4: AVENIDA - CALLE 9 # 50 - 85 SAN RAFAEL / | K4: MARIA CAMILA ALVAREZ | L4: 3113874244 | M4: 95632881 / BANCO DE BOGOTA | N4: LINK-QR
A5: POSTOBON | B5: GASEOSAS LUX SAS | C5: SE3RYFGAJY | D5: 0 | E5: Si | F5: Si | G5: Nequi, Efectivo | I5: 860001697 | J5: AC. 17 #39 / ZONA INDUSTRIAL | K5: MARIA CAMILA ALVAREZ | L5: 3113874244 | M5: 24156243887 / BANCOLOMBIA | N5: LINK-QR
A6: POSTOBON | B6: POSTOBON SA | C6: 6RIMATJBDJ | D6: 0 | E6: Si | F6: Si | G6: Nequi, Efectivo | I6: 890903939 | J6: CALLE 62 #44-77 AUTOPISTA SUR / POSTOBON ITAGUI | K6: MARIA CAMILA ALVAREZ | L6: 3113874244 | M6: 26833507931/ BANCOLOMBIA | N6: LINK-QR
A7: POSTOBON | B7: POSTOBON SA | C7: 4VETEWDH1L | D7: 0 | E7: Si | F7: Si | G7: Nequi, Efectivo | I7: 890903939 | J7: CALLE 52 # 47-42, Edificio Coltejer / POSTOBON BELLO | K7: MARIA CAMILA ALVAREZ | L7: 3113874244 | M7: 10032775656/ BANCOLOMBIA | N7: LINK-QR
A8: POSTOBON | B8: POSTOBON SA | C8: 6085Z6TTB7 | D8: 0 | E8: Si | F8: Si | G8: Nequi, Efectivo | H8: LINK DE APGO | I8: 890903939 | J8: Calle 52 # 47 - 42 / EDIFICIO COLTEJER / USUARIOS DOSQUEBRADAS/ | K8: MARIA CAMILA ALVAREZ | L8: 3113874244 | M8: 72501305555/ BANCOLOMBIA | N8: LINK-QR
A9: POSTOBON | B9: POSTOBON SA | C9: TOM95X6WAO | D9: 0 | E9: Si | F9: Si | G9: Nequi, Efectivo | I9: 890903939 | J9: SEDES. YUMBO-ZARSAL-BUGA-BUENAVENTURA-POPAYAN-JAMUNDI | K9: MARIA CAMILA ALVAREZ | L9: 3113874244 | M9: 245000182697 / BANCOLOMBIA | N9: LINK-QR
A10: POSTOBON | B10: POSTOBON SA | C10: 053AM2S3L4 | D10: 0 | E10: Si | F10: Si | G10: Nequi, Efectivo | I10: 890903939 | J10: Cucuta - Pamplona santander | K10: MARIA CAMILA ALVAREZ | L10: 3113874244 | M10: 24500003179 / BANCOLOMBIA | N10: LINK-QR
A11: POSTOBON | B11: POSTOBON SA | C11: Q7VR1248VT | D11: 0 | E11: Si | F11: Si | G11: Nequi, Efectivo | I11: 860001697 | J11: Piedecuesta-bucaramanga-giron-florida blanca | K11: MARIA CAMILA ALVAREZ | L11: 3113874244 | M11: 24500016809 / BANCOLOMBIA | N11: LINK-QR
A12: POSTOBON | B12: POSTOBON SA | C12: Z2LOEMM4GD | D12: 0 | E12: Si | F12: Si | G12: Nequi, Efectivo | I12: 890903939 | J12: Dg. 21 #54-40, Zapatero, Cartagena de Indias, Provincia de Cartagena, Bolívar | K12: MARIA CAMILA ALVAREZ | L12: 3113874244 | M12: 200020364 / BANCOLOMBIA | N12: LINK-QR
A13: POSTOBON | B13: POSTOBON SA | C13: 79GCNR6OJO | D13: 0 | E13: Si | F13: Si | G13: Nequi, Efectivo | I13: 890903939 | J13: MALAMBO BARRAQUILLA | K13: MARIA CAMILA ALVAREZ | L13: 3113874244 | M13: 24500010488 / BANCOLOMBIA | N13: LINK-QR
A14: POSTOBON | B14: GASEOSAS LUX | C14: R6S43QK37T | D14: 0 | E14: Si | F14: Si | G14: Nequi, Efectivo | I14: 860001697 | J14: Cra. 24a # 14-47, Villavicencio, Meta | K14: MARIA CAMILA ALVAREZ | L14: 3113874244 | M14: 24500003183 / BANCOLOMBIA | N14: LINK-QR
A15: POSTOBON | B15: GASEOSAS LUX | C15: PU7SF6NZY0 | D15: 0 | E15: Si | F15: Si | G15: Nequi, Efectivo | I15: 860001697 | J15: 40, Ibagué, Tolima | K15: MARIA CAMILA ALVAREZ | L15: 3113874244 | M15: 24500003184 / BANCOLOMBIA | N15: LINK-QR
A16: POSTOBON | B16: GASEOSAS LUX | C16: Y5CUZZXX7J | D16: 0 | E16: Si | F16: Si | G16: Nequi, Efectivo | I16: 860001697 | J16: Valledupar | K16: MARIA CAMILA ALVAREZ | L16: 3113874244 | M16: 24500003181 /BANCOLOMBIA | N16: LINK-QR
A17: POSTOBON | B17: GASEOSAS LUX | C17: SCXKIXA5L6 | D17: 0 | E17: Si | F17: Si | G17: Nequi, Efectivo | I17: 860001697 | J17: 23-357, Cra 5 #23-135, Neiva, Huila | K17: MARIA CAMILA ALVAREZ | L17: 3113874244 | N17: LINK-QR
A18: POSTOBON | B18: POSTOBON SA | C18: 8GCLJOWKQF | D18: 0 | E18: Si | F18: Si | G18: Nequi, Efectivo | I18: 890903939 | J18: Cra. 21a #28D-53, Comuna 4, Santa Marta, Magdalena | K18: MARIA CAMILA ALVAREZ | L18: 3113874244 | N18: LINK-QR
A19: POSTOBON | B19: GASEOSAS LUX | C19: GLKD99RUI4 | D19: 0 | E19: Si | F19: Si | G19: Nequi, Efectivo | I19: 860001697 | J19: Barrancabermeja / Gaseosas Lux Barranca | K19: MARIA CAMILA ALVAREZ | L19: 3113874244 | N19: LINK-QR
A20: POSTOBON | B20: GASEOSAS LUX | C20: 4KTN5UUBRO | D20: 0 | E20: Si | F20: Si | G20: Nequi, Efectivo | I20: 860001697 | J20: Duitama / Gaseosas Lux Duitama | K20: MARIA CAMILA ALVAREZ | L20: 3113874244 | N20: LINK-QR
A21: POSTOBON | B21: GASEOSAS LUX | C21: 14YAL4TC80 | D21: 0 | E21: Si | F21: Si | G21: Nequi, Efectivo | I21: 860001697 | J21: Gaseosas Lux Monteria | K21: MARIA CAMILA ALVAREZ | L21: 3113874244 | N21: LINK-QR
A22: POSTOBON | B22: GASEOSAS LUX | C22: D8WWQSR8UA | D22: 0 | E22: Si | F22: Si | G22: Nequi, Efectivo | I22: 860001697 | J22: Lux pasto | K22: MARIA CAMILA ALVAREZ | L22: 3113874244 | N22: LINK-QR
A23: POSTOBON | B23: POSTOBON SA | C23: 2KU5V7TSPF | D23: 0 | E23: Si | F23: Si | G23: Nequi, Efectivo | I23: 890903939 | J23: Chigorodo | K23: MARIA CAMILA ALVAREZ | L23: 3113874244 | N23: LINK-QR
A24: POSTOBON | B24: INVERSIONES TC SAS - TIENDAS CERCANAS | C24: L7QZVRPNHB | D24: 0 | E24: No aplica | F24: Si | G24: Nequi, Efectivo | H24: TODOS - APPI, MENOS PAGO EN EFECTIVO | I24: 902077218 | J24: TIENDAS CERCANAS - PROYECTO KAREN | K24: KAREN GONZALEZ | L24: 305 2566574 | N24: COMPLETO
A27: COLANTA | B27: AGROCOLANTA | C27: PA80NXKNGV | D27: 0 | E27: No aplica | F27: Si | J27: LIDER PROYECTO | K27: Orion Restrepo | L27: 3245298322 | M27: 39269999155 - DAVIVIENDA | N27: LINK-QR
A28: COLANTA | B28: COLANTA | C28: X6YO81UJK6 | D28: 0 | E28: Si | F28: Si | J28: ANALISTA CANAL TRADICIONAL | K28: Anni Carolina Peña | L28: 3245298322 | M28: 396270006440 - DAVIVIENDA | N28: LINK-QR
A29: COLANTA | B29: COLANTA | C29: RPNIJ33O92 | D29: 0 | E29: Si | F29: Si | J29: ANALISTA COMERCIALIZADORAS | K29: Nasly Gamboa | L29: 3245298322 | M29: 1890447809 - DAVIVIENDA | N29: DATAFONO - LINK
A30: COLANTA | B30: Capy COLANTA | C30: 65SK8AN59R | D30: 0 | E30: Si | F30: Si | J30: CONCILIACIÓN CUENTAS BANCARIAS | K30: Yohana Velasquez | L30: 3245298322 | M30: 558246880 - BBVA | N30: DATAFONO - LINK
A31: COLANTA | B31: COLANTA BASE | C31: VY6VES3Z9R | D31: 0 | E31: Si | F31: Si | J31: ANALISTA MERCOLANTA | K31: Orion Restrepo | L31: 3245298322 | M31: 558246880 - BBVA | N31: LINK-QR
A33: SULICOR | B33: SULICOR | C33: FUE3DBCUN3 | D33: 700 QR | E33: Si | F33: Si | J33: COORINADORA DEL PROYECTO | K33: Stephania Florez Garzon | L33: 3226013052 | M33: 7123971850 - BANCOLOMBIA | N33: QR
A34: SULICOR | B34: SULICOR | C34: FUE3DBCUN3 | J34: COORINADORA DEL PROYECTO | K34: Jaime Andres Hortua | L34: 3042147377 | M34: 7123971850 - BANCOLOMBIA | N34: QR
J35: COORINADORA DEL PROYECTO | K35: Tatiana Arena | L35: 3152090217 | M35: 7123971850 - BANCOLOMBIA | N35: QR
J36: JEFE DE CARTETA | K36: Juan Villalobos | L36: 3178833600 | M36: 7123971850 - BANCOLOMBIA | N36: QR
A38: TTB | B38: TTB SAS | C38: BTJHGRLYXZ | D38: Personalizado | E38: No aplica | F38: Si | H38: Parqueaderos IDU - Terminales con Proccis
A39: TTB | B39: TTB SAS | C39: 9I8LY96BBG | D39: Personalizado | E39: No aplica | F39: Si | H39: Parqueaderos IDU - Terminales con Proccis | N39: QR
A40: TTB | B40: TTB SAS | C40: H7H258JKKS | D40: Personalizado | E40: No aplica | F40: Si | H40: Parqueaderos Terminal dentro de la terminal de transporte | N40: QR
A41: TTB | B41: TTB SAS | C41: 3NQ4U0QUHW | D41: Personalizado | E41: No aplica | F41: Si | H41: Tasa de Uso - pendientes de las APIS | N41: QR
A42: TTB | B42: TTB SAS | C42: W7NPE2OB3Q | D42: Personalizado | E42: No aplica | F42: Si | H42: Zona de Parqueo Pago - GRUPO ZPP-silice | N42: QR
A43: TTB | B43: TTB SAS | C43: 5602GZ54UZ | D43: Personalizado | E43: No aplica | F43: Si | H43: Terminal de Transporte SA - SAlitre (Proccis)
A44: TTB | B44: TTB SAS | C44: JA82FIY0Z4 | D44: Personalizado | E44: No aplica | F44: Si | H44: Parqueaderos DADEP - Proccis
...

Sheet Hoja 14
A1: Merchant ID | B1: # | C1: TIPO DE DOCUMENTO | D1: # DE DOCUMENTO | E1: Ejecutivo que realiza la ACTIVACIÓN | F1: Fecha de ACTIVACIÓN | G1: Mes
A2: BGBKG6TM1S | B2: 1 | C2: CC | D2: 52272434 | E2: jeyson.salazar@bold.co | F2: 46018 | G2: 46018
A3: 2WZ9UO778I | B3: 2 | C3: CC | D3: 23965716 | E3: jeyson.salazar@bold.co | F3: 46018 | G3: 46018
A4: YQV101FLPR | B4: 3 | C4: CC | D4: 79944143 | E4: jeyson.salazar@bold.co | F4: 46071 | G4: 46071
A5: LBPEPJ7MSE | B5: 4 | C5: NIT | D5: 830000897 | E5: jeyson.salazar@bold.co | F5: 46071 | G5: 46071
A6: 5QI9HHZ4V3 | B6: 5 | C6: CC | D6: 19265207 | E6: jeyson.salazar@bold.co | F6: 46071 | G6: 46071
A7: 7IPCV8YYHF | B7: 6 | C7: NIT | D7: 901404715 | E7: jeyson.salazar@bold.co | F7: 46071 | G7: 46071
A8: AB5GBIOYD3 | B8: 7 | C8: NIT | D8: 901356768 | E8: jeyson.salazar@bold.co | F8: 46082 | G8: 46082
A9: D3G5KP2NFQ | B9: 8 | C9: CC | D9: 88177710 | E9: jeyson.salazar@bold.co | F9: 46085 | G9: 46085
A10: A51QMI6IBF | B10: 9 | C10: CC | D10: 45495943 | E10: jeyson.salazar@bold.co | F10: 46105 | G10: 46105
A11: MPCK701TYS | B11: 10 | C11: NIT | D11: 900364915 | E11: jeyson.salazar@bold.co | F11: 46083 | G11: 46083
